Assertion failed: h.bucket_count() == 0 (hash_map.pass.cpp: test_default_does_not_allocate: 28)
Assertion failed: h.bucket_count() == 0 (hash_set.pass.cpp: test_default_does_not_allocate: 28)

Assertion failed: false (db_copy.pass.cpp: main: 31)
Assertion failed: false (emplace_db1.pass.cpp: main: 47)

Assertion failed: false (erase_iter_db2.pass.cpp: main: 32)


Assertion failed: false (erase_iter_iter_db3.pass.cpp: main: 31)

Assertion failed: false (insert_iter_iter_iter_db1.pass.cpp: main: 37)
Assertion failed: false (insert_iter_rvalue_db1.pass.cpp: main: 30)
Assertion failed: false (insert_iter_size_value_db1.pass.cpp: main: 30)
Assertion failed: false (insert_iter_value_db1.pass.cpp: main: 32)

Assertion failed: false (db_splice_pos_list.pass.cpp: main: 31)
Assertion failed: false (db_splice_pos_list_iter.pass.cpp: main: 31)

Assertion failed: v.size() == 3 (asan_throw.pass.cpp: test_insert_range: 102)

Assertion failed: p.first.count == 2 (construct_piecewise_pair.pass.cpp: main: 121)
Assertion failed: AssertCount == 1 (db_deallocate.pass.cpp: main: 42)
Assertion failed: AssertCount >= 1 (db_deallocate.pass.cpp: main: 50)
Assertion failed: __gnu_cxx::hash<const char *>()("test") == std::hash<std::string>()("test") (specializations.pass.cpp: main: 20)




Assertion failed: std::equal(oa, oa + os, oa1) (sample.pass.cpp: test: 76)
Assertion failed: std::equal(ia, ia+sa, ia1) (random_shuffle.pass.cpp: main: 52)
Assertion failed: std::equal(ia, ia+sa, ia1) (random_shuffle_rand.pass.cpp: test_with_iterator: 48)
Assertion failed: std::equal(ia, ia+sa, ia1) (random_shuffle_urng.pass.cpp: main: 29)
Assertion failed: this != &rhs (inplace_merge.pass.cpp: operator=: 33)
Assertion failed: this != &rhs (inplace_merge_comp.pass.cpp: operator=: 42)
Assertion failed: c.max_size() <= max_dist (max_size.pass.cpp: main: 39)
Assertion failed: controller->check<Args&&...>() (/app/llvm-project/libcxx/test/support/container_test_types.h: construct: 311) ../../../map_allocator_requirement_test_templates.h:51 void testMapInsert() [with Container = std::map<CopyInsertable<1>, CopyInsertable<2>, std::less<CopyInsertable<1> >, ContainerTestAllocator<std::pair<const CopyInsertable<1>, CopyInsertable<2> >, std::pair<const CopyInsertable<1>, CopyInsertable<2> > > >]: Checkpoint 'Testing C::insert(value_type&)'
terminate called after throwing an instance of 'int'
Assertion failed: c.max_size() <= max_dist (max_size.pass.cpp: main: 39)
terminate called after throwing an instance of 'int'
Assertion failed: c.max_size() <= max_dist (max_size.pass.cpp: main: 38)
terminate called after throwing an instance of 'int'
Assertion failed: m1.empty() (move_alloc.pass.cpp: main: 102)
Assertion failed: controller->check<Args&&...>() (/app/llvm-project/libcxx/test/support/container_test_types.h: construct: 311) ../../set_allocator_requirement_test_templates.h:128 void testSetInsert() [with Container = std::set<CopyInsertable<1>, std::less<CopyInsertable<1> >, ContainerTestAllocator<CopyInsertable<1>, CopyInsertable<1> > >]: Checkpoint 'Testing C::insert(Iter, Iter) for *Iter = value_type&'
Assertion failed: c.max_size() <= max_dist (max_size.pass.cpp: main: 38)
terminate called after throwing an instance of 'int'
Assertion failed: m1.empty() (move_alloc.pass.cpp: main: 102)
Assertion failed: test_alloc_base::count == expected_num_allocs (allocator_move.pass.cpp: test: 35)
terminate called after throwing an instance of 'std::bad_alloc' what(): std::bad_alloc
terminate called after throwing an instance of 'std::bad_alloc' what(): std::bad_alloc
Assertion failed: c1.size() != 0 (move_alloc.pass.cpp: main: 38)
Assertion failed: c1.size() != 0 (move_assign.pass.cpp: main: 54)
terminate called after throwing an instance of 'std::bad_alloc' what(): std::bad_alloc
terminate called after throwing an instance of 'std::bad_alloc' what(): std::bad_alloc


Assertion failed: false (push_back_exception_safety.pass.cpp: main: 96)
Assertion failed: cii - ii1 == 0 (iterators.pass.cpp: main: 69)

Assertion failed: old_size - std::distance(l.begin(), l.end()) == expected (remove_if.pass.cpp: do_remove_if: 35)
Assertion failed: *i == t1[n1] (splice_after_range.pass.cpp: testd: 39)
Assertion failed: c.max_size() <= max_dist (max_size.pass.cpp: main: 36)
Assertion failed: c.max_size() <= max_dist (max_size.pass.cpp: main: 35)
Assertion failed: !l.empty() (assign_move.pass.cpp: main: 48)
Assertion failed: !l.empty() (move_alloc.pass.cpp: main: 33)
Assertion failed: c.max_size() == max_dist (max_size.pass.cpp: main: 37)
Assertion failed: !l.empty() (assign_move.pass.cpp: main: 57)
Assertion failed: !l.empty() (move_alloc.pass.cpp: main: 39)
terminate called after throwing an instance of 'std::bad_alloc' what(): std::bad_alloc
Assertion failed: c.bucket_count() == 0 (bucket_count.pass.cpp: main: 29)
Assertion failed: c.max_size() <= max_dist (max_size.pass.cpp: main: 41)
Assertion failed: c1.bucket_count() == 0 (swap_member.pass.cpp: main: 40)
Assertion failed: c.bucket_count() == 0 (allocator.pass.cpp: main: 37)
Assertion failed: c.bucket_count() == 0 (default.pass.cpp: main: 37)
Assertion failed: controller->check<Args&&...>() (/app/llvm-project/libcxx/test/support/container_test_types.h: construct: 311) ../../../map_allocator_requirement_test_templates.h:51 void testMapInsert() [with Container = std::unordered_map<CopyInsertable<1>, CopyInsertable<2>, std::hash<CopyInsertable<1> >, std::equal_to<CopyInsertable<1> >, ContainerTestAllocator<std::pair<const CopyInsertable<1>, CopyInsertable<2> >, std::pair<const CopyInsertable<1>, CopyInsertable<2> > > >]: Checkpoint 'Testing C::insert(value_type&)'
terminate called after throwing an instance of 'int'
Assertion failed: c1.bucket_count() == 0 (swap_non_member.pass.cpp: main: 40)
Assertion failed: c.bucket_count() == 0 (bucket_count.pass.cpp: main: 28)
Assertion failed: c.max_size() <= max_dist (max_size.pass.cpp: main: 43)
Assertion failed: c.bucket_count() == 3 (rehash.pass.cpp: main: 108)
Assertion failed: c.bucket_count() == 3 (reserve.pass.cpp: main: 86)
Assertion failed: c1.bucket_count() == 0 (swap_member.pass.cpp: main: 42)
Assertion failed: c.bucket_count() == 0 (allocator.pass.cpp: main: 37)
Assertion failed: c.bucket_count() == 0 (default.pass.cpp: main: 37)
Assertion failed: r == next(c.begin()) (emplace_hint.pass.cpp: main: 45)
terminate called after throwing an instance of 'int'
Assertion failed: c1.bucket_count() == 0 (swap_non_member.pass.cpp: main: 42)
Assertion failed: c.bucket_count() == 0 (bucket_count.pass.cpp: main: 28)
Assertion failed: c.max_size() <= max_dist (max_size.pass.cpp: main: 42)
terminate called after throwing an instance of 'int'
Assertion failed: c.bucket_count() == 3 (rehash.pass.cpp: main: 63)
Assertion failed: c.bucket_count() == 3 (reserve.pass.cpp: main: 70)
Assertion failed: c1.bucket_count() == 0 (swap_member.pass.cpp: main: 39)
Assertion failed: c.bucket_count() == 0 (allocator.pass.cpp: main: 36)
Assertion failed: c.bucket_count() == 0 (default.pass.cpp: main: 36)
Assertion failed: c1.bucket_count() == 0 (swap_non_member.pass.cpp: main: 39)
Assertion failed: c.bucket_count() == 0 (bucket_count.pass.cpp: main: 28)
Assertion failed: controller->check<Args&&...>() (/app/llvm-project/libcxx/test/support/container_test_types.h: construct: 311) ../../set_allocator_requirement_test_templates.h:128 void testSetInsert() [with Container = std::unordered_set<CopyInsertable<1>, std::hash<CopyInsertable<1> >, std::equal_to<CopyInsertable<1> >, ContainerTestAllocator<CopyInsertable<1>, CopyInsertable<1> > >]: Checkpoint 'Testing C::insert(Iter, Iter) for *Iter = value_type&'
Assertion failed: c.max_size() <= max_dist (max_size.pass.cpp: main: 38)
terminate called after throwing an instance of 'int'
Assertion failed: c1.bucket_count() == 0 (swap_member.pass.cpp: main: 39)
Assertion failed: c.bucket_count() == 0 (allocator.pass.cpp: main: 36)
Assertion failed: c.bucket_count() == 0 (default.pass.cpp: main: 36)
Assertion failed: c1.bucket_count() == 0 (swap_non_member.pass.cpp: main: 39)
Assertion failed: out.fail() (freeze.pass.cpp: main: 27)
Assertion failed: out.fail() (freeze.pass.cpp: main: 27)
Assertion failed: called == 0 (custom_alloc.pass.cpp: main: 47)
Assertion failed: s.str() == nullptr (default.pass.cpp: main: 24)
Assertion failed: sb.sputc('a') == EOF (freeze.pass.cpp: main: 25)
Assertion failed: sb.pubseekoff(3, std::ios_base::cur, std::ios_base::in | std::ios_base::out) == -1 (seekoff.pass.cpp: main: 30)
Assertion failed: sb.pubseekpos(3, std::ios_base::in) == 3 (seekpos.pass.cpp: main: 28)
Assertion failed: msg.rfind("Unknown error", 0) == 0 (generic_category.pass.cpp: test_message_for_bad_value: 33)
Assertion failed: msg.rfind("Unknown error", 0) == 0 (system_category.pass.cpp: test_message_for_bad_value: 33)
Assertion failed: result == static_cast<std::size_t>(i) (error_code.pass.cpp: test: 35)
Assertion failed: result == static_cast<std::size_t>(i) (error_condition.pass.cpp: test: 35)
Assertion failed: false (allocate.pass.cpp: testAllocForSizeThrows: 67)
UsesAllocatorType's don't match: Assertion failed: (doTest<T, U>(UA_None, UA_None, p)) (construct_pair_const_lvalue_pair.pass.cpp: test_pmr_not_uses_allocator: 103)
UsesAllocatorType's don't match: Assertion failed: (doTest<T, U>(UA_None, UA_None, std::move(p))) (construct_pair_rvalue.pass.cpp: test_pmr_not_uses_allocator: 102)
UsesAllocatorType's don't match: Assertion failed: (doTest<T, U>(UA_None, UA_None, std::forward<TT>(t), std::forward<UU>(u))) (construct_pair_values.pass.cpp: test_pmr_not_uses_allocator: 106)
UsesAllocatorType's don't match: Assertion failed: (doTest<T, U>(UA_None, UA_None, std::move(ttuple), std::move(utuple))) (construct_piecewise_pair.pass.cpp: test_pmr_not_uses_allocator: 96)
Assertion failed: p->second.holds(42, pma) (construct_piecewise_pair_evil.pass.cpp: test_evil: 116)
UsesAllocatorType's don't match: Assertion failed: (doTest<T>(UA_None, std::forward<Args>(args)...)) (construct_types.pass.cpp: test_pmr_not_uses_alloc: 145)
Assertion failed: P.checkAllocAtLeast(ret, s, align_exp) (do_allocate_and_deallocate.pass.cpp: check_allocate_deallocate: 48)
Assertion failed: f.pptr() == f.pbase() (overflow.pass.cpp: main: 51)
Assertion failed: f.open("underflow.dat", std::ios_base::in) != 0 (pbackfail.pass.cpp: main: 41)
Assertion failed: buf[0] == 'v' (seekoff.pass.cpp: main: 34)
Assertion failed: f.open("underflow.dat", std::ios_base::in) != 0 (underflow.pass.cpp: main: 45)
Assertion failed: x == 4.5 (member_swap.pass.cpp: main: 31)
Assertion failed: x == 3.25 (move_assign.pass.cpp: main: 32)
Assertion failed: x == 4.5 (nonmember_swap.pass.cpp: main: 32)
Assertion failed: x == 3.25 (move.pass.cpp: main: 31)
Assertion failed: x == 3.25 (pointer.pass.cpp: main: 29)
Assertion failed: x == 3.25 (string.pass.cpp: main: 29)
Assertion failed: fs.is_open() (close.pass.cpp: main: 29)
Assertion failed: fs.is_open() (open_path.pass.cpp: main: 35)
Assertion failed: fs.is_open() (open_pointer.pass.cpp: main: 33)
Assertion failed: fs.is_open() (open_string.pass.cpp: main: 33)
Assertion failed: fb->sgetc() == 'r' (rdbuf.pass.cpp: main: 28)
In path_ec_ctor():72 Assertion TEST_CHECK(e.path() == p) failed. in file: path.pass.cpp Test case FAILED with uncaught exception: last checkpoint near path.pass.cpp::95 void directory_entry_path_ctor_suite::path_ctor_calls_refresh() In path_ctor_dne():130 Assertion TEST_CHECK(ent.path() == static_env.DNE) failed. in file: path.pass.cpp In path_ctor_cannot_resolve():162 Assertion TEST_CHECK(ErrorIs(ec, std::errc::permission_denied)) failed. in file: path.pass.cpp In path_ctor_cannot_resolve():168 Assertion TEST_CHECK(ErrorIs(ec, std::errc::permission_denied)) failed. in file: path.pass.cpp Summary for testsuite directory_entry_path_ctor_suite: 1 of 5 test cases passed. 20 of 24 assertions passed. 0 unsupported test cases.
In test_assign_calls_refresh():96 Assertion TEST_CHECK(ent.is_regular_file()) failed. in file: assign.pass.cpp In test_assign_propagates_error():115 Assertion TEST_CHECK(ErrorIs(ec, std::errc::permission_denied)) failed. in file: assign.pass.cpp In test_assign_propagates_error():121 Assertion TEST_CHECK(ErrorIs(ec, std::errc::permission_denied)) failed. in file: assign.pass.cpp Summary for testsuite directory_entry_mods_suite: 2 of 4 test cases passed. 8 of 11 assertions passed. 0 unsupported test cases.
In refresh_on_bad_symlink():117 Assertion TEST_CHECK(ent.is_regular_file()) failed. in file: refresh.pass.cpp In refresh_on_bad_symlink():118 Assertion TEST_CHECK(ent.exists()) failed. in file: refresh.pass.cpp In refresh_on_bad_symlink():134 Assertion TEST_CHECK(ent.is_regular_file()) failed. in file: refresh.pass.cpp In refresh_on_bad_symlink():135 Assertion TEST_CHECK(ent.exists()) failed. in file: refresh.pass.cpp In refresh_cannot_resolve():167 Assertion TEST_CHECK(ErrorIs(ec, std::errc::permission_denied)) failed. in file: refresh.pass.cpp In refresh_cannot_resolve():172 Assertion TEST_CHECK_THROW_RESULT(filesystem_error,Checker,ent.refresh()) failed. in file: refresh.pass.cpp In refresh_cannot_resolve():182 Assertion TEST_CHECK(ErrorIs(ec, std::errc::permission_denied)) failed. in file: refresh.pass.cpp In refresh_cannot_resolve():187 Assertion TEST_CHECK_THROW_RESULT(filesystem_error,Checker,ent.refresh()) failed. in file: refresh.pass.cpp In refresh_cannot_resolve():203 Assertion TEST_CHECK(ent.exists(ec) == false) failed. in file: refresh.pass.cpp In refresh_cannot_resolve():204 Assertion TEST_CHECK(ErrorIs(ec, std::errc::permission_denied)) failed. in file: refresh.pass.cpp In refresh_cannot_resolve():216 Assertion TEST_CHECK_THROW(filesystem_error,ent_file.refresh()) failed. in file: refresh.pass.cpp In refresh_cannot_resolve():217 Assertion TEST_CHECK_THROW(filesystem_error,ent_sym.refresh()) failed. in file: refresh.pass.cpp In access_cache_after_refresh_fails():295 Assertion TEST_CHECK(ErrorIs(ec, std::errc::permission_denied)) failed. in file: refresh.pass.cpp In access_cache_after_refresh_fails():297 Assertion TEST_CHECK(ent.exists(ec) == false) failed. in file: refresh.pass.cpp In access_cache_after_refresh_fails():297 Assertion TEST_CHECK(ErrorIs(ec, std::errc::permission_denied)) failed. in file: refresh.pass.cpp In access_cache_after_refresh_fails():298 Assertion TEST_CHECK(ErrorIs(ec, std::errc::permission_denied)) failed. in file: refresh.pass.cpp In access_cache_after_refresh_fails():299 Assertion TEST_CHECK(ent.last_write_time(ec) == file_time_type::min()) failed. in file: refresh.pass.cpp In access_cache_after_refresh_fails():299 Assertion TEST_CHECK(ErrorIs(ec, std::errc::permission_denied)) failed. in file: refresh.pass.cpp In access_cache_after_refresh_fails():300 Assertion TEST_CHECK(ent.hard_link_count(ec) == uintmax_t(-1)) failed. in file: refresh.pass.cpp In access_cache_after_refresh_fails():300 Assertion TEST_CHECK(ErrorIs(ec, std::errc::permission_denied)) failed. in file: refresh.pass.cpp In access_cache_after_refresh_fails():312 Assertion TEST_CHECK(ErrorIs(ec, std::errc::permission_denied)) failed. in file: refresh.pass.cpp In access_cache_after_refresh_fails():314 Assertion TEST_CHECK(ent.exists(ec) == false) failed. in file: refresh.pass.cpp In access_cache_after_refresh_fails():314 Assertion TEST_CHECK(ErrorIs(ec, std::errc::permission_denied)) failed. in file: refresh.pass.cpp In access_cache_after_refresh_fails():315 Assertion TEST_CHECK(ent.is_symlink(ec) == false) failed. in file: refresh.pass.cpp In access_cache_after_refresh_fails():315 Assertion TEST_CHECK(ErrorIs(ec, std::errc::permission_denied)) failed. in file: refresh.pass.cpp In access_cache_after_refresh_fails():316 Assertion TEST_CHECK(ent.last_write_time(ec) == file_time_type::min()) failed. in file: refresh.pass.cpp In access_cache_after_refresh_fails():316 Assertion TEST_CHECK(ErrorIs(ec, std::errc::permission_denied)) failed. in file: refresh.pass.cpp In access_cache_after_refresh_fails():317 Assertion TEST_CHECK(ent.hard_link_count(ec) == uintmax_t(-1)) failed. in file: refresh.pass.cpp In access_cache_after_refresh_fails():317 Assertion TEST_CHECK(ErrorIs(ec, std::errc::permission_denied)) failed. in file: refresh.pass.cpp In access_cache_after_refresh_fails():332 Assertion TEST_CHECK(ent.exists(ec) == false) failed. in file: refresh.pass.cpp In access_cache_after_refresh_fails():332 Assertion TEST_CHECK(ErrorIs(ec, std::errc::permission_denied)) failed. in file: refresh.pass.cpp In access_cache_after_refresh_fails():333 Assertion TEST_CHECK(ent.is_regular_file(ec) == false) failed. in file: refresh.pass.cpp In access_cache_after_refresh_fails():333 Assertion TEST_CHECK(ErrorIs(ec, std::errc::permission_denied)) failed. in file: refresh.pass.cpp In access_cache_after_refresh_fails():334 Assertion TEST_CHECK(ent.last_write_time(ec) == file_time_type::min()) failed. in file: refresh.pass.cpp In access_cache_after_refresh_fails():334 Assertion TEST_CHECK(ErrorIs(ec, std::errc::permission_denied)) failed. in file: refresh.pass.cpp In access_cache_after_refresh_fails():335 Assertion TEST_CHECK(ent.hard_link_count(ec) == uintmax_t(-1)) failed. in file: refresh.pass.cpp In access_cache_after_refresh_fails():335 Assertion TEST_CHECK(ErrorIs(ec, std::errc::permission_denied)) failed. in file: refresh.pass.cpp Summary for testsuite directory_entry_mods_suite: 4 of 7 test cases passed. 48 of 85 assertions passed. 0 unsupported test cases.
Test case FAILED with uncaught exception: last checkpoint near replace_filename.pass.cpp::109 void directory_entry_mods_suite::test_replace_filename_calls_refresh() In test_replace_filename_propagates_error():145 Assertion TEST_CHECK(ErrorIs(ec, std::errc::permission_denied)) failed. in file: replace_filename.pass.cpp In test_replace_filename_propagates_error():153 Assertion TEST_CHECK(ErrorIs(ec, std::errc::permission_denied)) failed. in file: replace_filename.pass.cpp In test_replace_filename_propagates_error():164 Assertion TEST_CHECK(!ent.exists(ec)) failed. in file: replace_filename.pass.cpp In test_replace_filename_propagates_error():165 Assertion TEST_CHECK(ErrorIs(ec, std::errc::permission_denied)) failed. in file: replace_filename.pass.cpp Summary for testsuite directory_entry_mods_suite: 2 of 4 test cases passed. 13 of 17 assertions passed. 0 unsupported test cases.
In basic():61 Assertion TEST_CHECK(ent.file_size(ec) == expect) failed. in file: file_size.pass.cpp In basic():62 Assertion TEST_CHECK(!ec) failed. in file: file_size.pass.cpp In basic():74 Assertion TEST_CHECK(ent.file_size(ec) == 99) failed. in file: file_size.pass.cpp In basic():75 Assertion TEST_CHECK(!ec) failed. in file: file_size.pass.cpp In check_libcxx_string(const std::filesystem::__cxx11::filesystem_error&):556 Assertion TEST_CHECK(format == Err.what()) failed. in file: /app/llvm-project/libcxx/test/support/filesystem_test_helper.h filesystem_error::what() does not match expected output: expected: "filesystem error: in directory_entry::file_size: Is a directory [/tmp/test.e72d8e/dir]" actual: "filesystem error: cannot get file size: Is a directory [/tmp/test.e72d8e/dir]" In check_libcxx_string(const std::filesystem::__cxx11::filesystem_error&):556 Assertion TEST_CHECK(format == Err.what()) failed. in file: /app/llvm-project/libcxx/test/support/filesystem_test_helper.h filesystem_error::what() does not match expected output: expected: "filesystem error: in directory_entry::file_size: Not supported [/tmp/test.e72d8e/fifo]" actual: "filesystem error: cannot get file size: Not supported [/tmp/test.e72d8e/fifo]" In check_libcxx_string(const std::filesystem::__cxx11::filesystem_error&):556 Assertion TEST_CHECK(format == Err.what()) failed. in file: /app/llvm-project/libcxx/test/support/filesystem_test_helper.h filesystem_error::what() does not match expected output: expected: "filesystem error: in directory_entry::file_size: Is a directory [/tmp/test.e72d8e/sym]" actual: "filesystem error: cannot get file size: Is a directory [/tmp/test.e72d8e/sym]" In check_libcxx_string(const std::filesystem::__cxx11::filesystem_error&):556 Assertion TEST_CHECK(format == Err.what()) failed. in file: /app/llvm-project/libcxx/test/support/filesystem_test_helper.h filesystem_error::what() does not match expected output: expected: "filesystem error: in directory_entry::file_size: No such file or directory [/tmp/test.dea0e3/DNE]" actual: "filesystem error: cannot get file size: No such file or directory [/tmp/test.dea0e3/DNE]" In check_libcxx_string(const std::filesystem::__cxx11::filesystem_error&):556 Assertion TEST_CHECK(format == Err.what()) failed. in file: /app/llvm-project/libcxx/test/support/filesystem_test_helper.h filesystem_error::what() does not match expected output: expected: "filesystem error: in directory_entry::file_size: No such file or directory [/tmp/test.dea0e3/bad_symlink]" actual: "filesystem error: cannot get file size: No such file or directory [/tmp/test.dea0e3/bad_symlink]" In error_reporting():175 Assertion TEST_CHECK(ErrorIs(ec, std::errc::permission_denied)) failed. in file: file_size.pass.cpp In error_reporting():178 Assertion TEST_CHECK(ent.file_size(ec) == uintmax_t(-1)) failed. in file: file_size.pass.cpp In error_reporting():179 Assertion TEST_CHECK(ErrorIs(ec, std::errc::permission_denied)) failed. in file: file_size.pass.cpp In error_reporting():182 Assertion TEST_CHECK_THROW_RESULT(filesystem_error,Checker,ent.file_size()) failed. in file: file_size.pass.cpp In error_reporting():200 Assertion TEST_CHECK(ErrorIs(ec, std::errc::permission_denied)) failed. in file: file_size.pass.cpp In error_reporting():203 Assertion TEST_CHECK(ent.file_size(ec) == uintmax_t(-1)) failed. in file: file_size.pass.cpp In error_reporting():204 Assertion TEST_CHECK(ErrorIs(ec, std::errc::permission_denied)) failed. in file: file_size.pass.cpp In error_reporting():208 Assertion TEST_CHECK_THROW_RESULT(filesystem_error,Checker,ent.file_size()) failed. in file: file_size.pass.cpp In error_reporting():229 Assertion TEST_CHECK(ent.file_size(ec) == uintmax_t(-1)) failed. in file: file_size.pass.cpp In error_reporting():230 Assertion TEST_CHECK(ErrorIs(ec, std::errc::permission_denied)) failed. in file: file_size.pass.cpp In error_reporting():234 Assertion TEST_CHECK_THROW_RESULT(filesystem_error,Checker,ent.file_size()) failed. in file: file_size.pass.cpp Summary for testsuite directory_entry_obs_testsuite: 1 of 4 test cases passed. 60 of 80 assertions passed. 0 unsupported test cases.
In test_with_ec():143 Assertion TEST_CHECK(CheckEC(sym_status_ec)) failed. in file: file_type_obs.pass.cpp In test_with_ec():143 Assertion TEST_CHECK(CheckEC(sym_status_ec)) failed. in file: file_type_obs.pass.cpp In test_with_ec():143 Assertion TEST_CHECK(CheckEC(sym_status_ec)) failed. in file: file_type_obs.pass.cpp In test_with_ec():143 Assertion TEST_CHECK(CheckEC(sym_status_ec)) failed. in file: file_type_obs.pass.cpp In test_with_ec_dne():168 Assertion TEST_CHECK(CheckEC(status_ec)) failed. in file: file_type_obs.pass.cpp In test_with_ec_dne():171 Assertion TEST_CHECK(CheckEC(status_ec)) failed. in file: file_type_obs.pass.cpp In test_with_ec_dne():174 Assertion TEST_CHECK(CheckEC(status_ec)) failed. in file: file_type_obs.pass.cpp In test_with_ec_dne():177 Assertion TEST_CHECK(CheckEC(status_ec)) failed. in file: file_type_obs.pass.cpp In test_with_ec_dne():180 Assertion TEST_CHECK(CheckEC(status_ec)) failed. in file: file_type_obs.pass.cpp In test_with_ec_dne():183 Assertion TEST_CHECK(CheckEC(status_ec)) failed. in file: file_type_obs.pass.cpp In test_with_ec_dne():186 Assertion TEST_CHECK(CheckEC(status_ec)) failed. in file: file_type_obs.pass.cpp In test_with_ec_dne():189 Assertion TEST_CHECK(CheckEC(status_ec)) failed. in file: file_type_obs.pass.cpp In test_with_ec_dne():192 Assertion TEST_CHECK(CheckEC(sym_status_ec)) failed. in file: file_type_obs.pass.cpp In test_with_ec_dne():192 Assertion TEST_CHECK(CheckEC(sym_status_ec)) failed. in file: file_type_obs.pass.cpp In test_with_ec_cannot_resolve():217 Assertion TEST_REQUIRE(dummy_ec) failed. in file: file_type_obs.pass.cpp Summary for testsuite directory_entry_obs_testsuite: 3 of 6 test cases passed. 150 of 165 assertions passed. 0 unsupported test cases.
In basic():58 Assertion TEST_CHECK(ent.hard_link_count(ec) == expect) failed. in file: hard_link_count.pass.cpp In basic():59 Assertion TEST_CHECK(!ec) failed. in file: hard_link_count.pass.cpp In basic():68 Assertion TEST_CHECK(ent.hard_link_count(ec) == expect) failed. in file: hard_link_count.pass.cpp In basic():69 Assertion TEST_CHECK(!ec) failed. in file: hard_link_count.pass.cpp In check_libcxx_string(const std::filesystem::__cxx11::filesystem_error&):556 Assertion TEST_CHECK(format == Err.what()) failed. in file: /app/llvm-project/libcxx/test/support/filesystem_test_helper.h filesystem_error::what() does not match expected output: expected: "filesystem error: in directory_entry::hard_link_count: No such file or directory [/tmp/test.325341/DNE]" actual: "filesystem error: cannot get link count: No such file or directory [/tmp/test.325341/DNE]" In check_libcxx_string(const std::filesystem::__cxx11::filesystem_error&):556 Assertion TEST_CHECK(format == Err.what()) failed. in file: /app/llvm-project/libcxx/test/support/filesystem_test_helper.h filesystem_error::what() does not match expected output: expected: "filesystem error: in directory_entry::hard_link_count: No such file or directory [/tmp/test.325341/bad_symlink]" actual: "filesystem error: cannot get link count: No such file or directory [/tmp/test.325341/bad_symlink]" In error_reporting():174 Assertion TEST_CHECK(ErrorIs(ec, std::errc::permission_denied)) failed. in file: hard_link_count.pass.cpp In error_reporting():177 Assertion TEST_CHECK(ent.hard_link_count(ec) == uintmax_t(-1)) failed. in file: hard_link_count.pass.cpp In error_reporting():178 Assertion TEST_CHECK(ErrorIs(ec, std::errc::permission_denied)) failed. in file: hard_link_count.pass.cpp In error_reporting():182 Assertion TEST_CHECK_THROW_RESULT(filesystem_error,Checker,ent.hard_link_count()) failed. in file: hard_link_count.pass.cpp In error_reporting():200 Assertion TEST_CHECK(ErrorIs(ec, std::errc::permission_denied)) failed. in file: hard_link_count.pass.cpp In error_reporting():203 Assertion TEST_CHECK(ent.hard_link_count(ec) == uintmax_t(-1)) failed. in file: hard_link_count.pass.cpp In error_reporting():204 Assertion TEST_CHECK(ErrorIs(ec, std::errc::permission_denied)) failed. in file: hard_link_count.pass.cpp In error_reporting():208 Assertion TEST_CHECK_THROW_RESULT(filesystem_error,Checker,ent.hard_link_count()) failed. in file: hard_link_count.pass.cpp In error_reporting():229 Assertion TEST_CHECK(ent.hard_link_count(ec) == uintmax_t(-1)) failed. in file: hard_link_count.pass.cpp In error_reporting():230 Assertion TEST_CHECK(ErrorIs(ec, std::errc::permission_denied)) failed. in file: hard_link_count.pass.cpp In error_reporting():234 Assertion TEST_CHECK_THROW_RESULT(filesystem_error,Checker,ent.hard_link_count()) failed. in file: hard_link_count.pass.cpp Summary for testsuite directory_entry_obs_testsuite: 2 of 4 test cases passed. 46 of 63 assertions passed. 0 unsupported test cases.
In basic():59 Assertion TEST_CHECK(ent.last_write_time(ec) == expect) failed. in file: last_write_time.pass.cpp In basic():60 Assertion TEST_CHECK(!ec) failed. in file: last_write_time.pass.cpp In basic():69 Assertion TEST_CHECK(ent.last_write_time(ec) == expect) failed. in file: last_write_time.pass.cpp In basic():70 Assertion TEST_CHECK(!ec) failed. in file: last_write_time.pass.cpp In check_libcxx_string(const std::filesystem::__cxx11::filesystem_error&):556 Assertion TEST_CHECK(format == Err.what()) failed. in file: /app/llvm-project/libcxx/test/support/filesystem_test_helper.h filesystem_error::what() does not match expected output: expected: "filesystem error: in directory_entry::last_write_time: No such file or directory [/tmp/test.6b866b/DNE]" actual: "filesystem error: cannot get file time: No such file or directory [/tmp/test.6b866b/DNE]" In check_libcxx_string(const std::filesystem::__cxx11::filesystem_error&):556 Assertion TEST_CHECK(format == Err.what()) failed. in file: /app/llvm-project/libcxx/test/support/filesystem_test_helper.h filesystem_error::what() does not match expected output: expected: "filesystem error: in directory_entry::last_write_time: No such file or directory [/tmp/test.6b866b/bad_symlink]" actual: "filesystem error: cannot get file time: No such file or directory [/tmp/test.6b866b/bad_symlink]" In error_reporting():147 Assertion TEST_CHECK(ErrorIs(ec, std::errc::permission_denied)) failed. in file: last_write_time.pass.cpp In error_reporting():150 Assertion TEST_CHECK(ent.last_write_time(ec) == file_time_type::min()) failed. in file: last_write_time.pass.cpp In error_reporting():151 Assertion TEST_CHECK(ErrorIs(ec, std::errc::permission_denied)) failed. in file: last_write_time.pass.cpp In error_reporting():155 Assertion TEST_CHECK_THROW_RESULT(filesystem_error,Checker,ent.last_write_time()) failed. in file: last_write_time.pass.cpp In error_reporting():173 Assertion TEST_CHECK(ErrorIs(ec, std::errc::permission_denied)) failed. in file: last_write_time.pass.cpp In error_reporting():176 Assertion TEST_CHECK(ent.last_write_time(ec) == file_time_type::min()) failed. in file: last_write_time.pass.cpp In error_reporting():177 Assertion TEST_CHECK(ErrorIs(ec, std::errc::permission_denied)) failed. in file: last_write_time.pass.cpp In error_reporting():181 Assertion TEST_CHECK_THROW_RESULT(filesystem_error,Checker,ent.last_write_time()) failed. in file: last_write_time.pass.cpp In error_reporting():202 Assertion TEST_CHECK(ent.last_write_time(ec) == file_time_type::min()) failed. in file: last_write_time.pass.cpp In error_reporting():203 Assertion TEST_CHECK(ErrorIs(ec, std::errc::permission_denied)) failed. in file: last_write_time.pass.cpp In error_reporting():207 Assertion TEST_CHECK_THROW_RESULT(filesystem_error,Checker,ent.last_write_time()) failed. in file: last_write_time.pass.cpp Summary for testsuite directory_entry_obs_testsuite: 1 of 3 test cases passed. 33 of 50 assertions passed. 0 unsupported test cases.
In access_denied_test_case():109 Assertion TEST_REQUIRE(ec) failed. in file: ctor.pass.cpp Summary for testsuite directory_iterator_constructor_tests: 9 of 10 test cases passed. 37 of 38 assertions passed. 0 unsupported test cases.
path.decompose.pass.cpp:152 void decompPathTest(): Assertion 'CheckCollectionsEqual(p.begin(), p.end(), TC.elements.begin(), TC.elements.end())' failed. Element 0 mismatched: `"//"` != `/`! LHS = ["//"] RHS = [/] path.decompose.pass.cpp:123 void decompPathTest(): Checkpoint '//'
TEST CASE #33 FAILED: Input: '//' Expected: '/' Output: '//' TEST CASE #34 FAILED: Input: '///' Expected: '/' Output: '///'
Assertion failed: MAlloc::alloc_count == 0 (string_alloc.pass.cpp: doShortStringTest: 58)
Assertion failed: p_in.native() == (const char*)InStr (path.io.unicode_bug.pass.cpp: doIOTest: 59)
In access_denied_test_case():111 Assertion TEST_REQUIRE(ec) failed. in file: ctor.pass.cpp Summary for testsuite recursive_directory_iterator_constructor_tests: 7 of 8 test cases passed. 38 of 39 assertions passed. 0 unsupported test cases.
In access_denied_on_recursion_test_case():176 Assertion TEST_CHECK(ec) failed. in file: increment.pass.cpp In access_denied_on_recursion_test_case():177 Assertion TEST_CHECK(it == endIt) failed. in file: increment.pass.cpp In access_denied_on_recursion_test_case():189 Assertion TEST_REQUIRE_THROW(filesystem_error,++it) failed. in file: increment.pass.cpp In test_PR35078():289 Assertion TEST_CHECK(ec) failed. in file: increment.pass.cpp In test_PR35078():290 Assertion TEST_CHECK(ec == eacess_ec) failed. in file: increment.pass.cpp In test_PR35078():291 Assertion TEST_CHECK(it == endIt) failed. in file: increment.pass.cpp In test_PR35078():302 Assertion TEST_CHECK(it == endIt) failed. in file: increment.pass.cpp In test_PR35078():318 Assertion TEST_CHECK_THROW_RESULT(filesystem_error,Checker,++it) failed. in file: increment.pass.cpp In test_PR35078_with_symlink():399 Assertion TEST_CHECK(ec) failed. in file: increment.pass.cpp In test_PR35078_with_symlink():400 Assertion TEST_CHECK(ec == eacess_ec) failed. in file: increment.pass.cpp In test_PR35078_with_symlink_file():490 Assertion TEST_CHECK(ec) failed. in file: increment.pass.cpp In test_PR35078_with_symlink_file():491 Assertion TEST_CHECK(ec == eacess_ec) failed. in file: increment.pass.cpp Summary for testsuite recursive_directory_iterator_increment_tests: 5 of 9 test cases passed. 188 of 200 assertions passed. 0 unsupported test cases.
In value_after_copy_construction_and_assignment_test():48 Assertion TEST_REQUIRE(rec_pending_it.recursion_pending() == true) failed. in file: recursion_pending.pass.cpp
In basic_test():51 Assertion TEST_CHECK(!ec) failed. in file: absolute.pass.cpp In basic_test():52 Assertion TEST_CHECK(ret.is_absolute()) failed. in file: absolute.pass.cpp In basic_test():53 Assertion TEST_CHECK(PathEq(ret, TC.expect)) failed. in file: absolute.pass.cpp Summary for testsuite filesystem_absolute_path_test_suite: 1 of 2 test cases passed. 9 of 12 assertions passed. 0 unsupported test cases.
In test_exception_contains_paths():106 Assertion TEST_CHECK(err.path2() == current_path()) failed. in file: canonical.pass.cpp In test_exception_contains_paths():114 Assertion TEST_CHECK(err.path2() == static_env.Dir) failed. in file: canonical.pass.cpp Summary for testsuite filesystem_canonical_path_test_suite: 3 of 4 test cases passed. 42 of 44 assertions passed. 0 unsupported test cases.
In check_libcxx_string(const std::filesystem::__cxx11::filesystem_error&):556 Assertion TEST_CHECK(format == Err.what()) failed. in file: /app/llvm-project/libcxx/test/support/filesystem_test_helper.h filesystem_error::what() does not match expected output: expected: "filesystem error: in copy_file: File exists [/tmp/test.c01024/file1] [/tmp/test.c01024/file1]" actual: "filesystem error: cannot copy file: File exists [/tmp/test.c01024/file1] [/tmp/test.c01024/file1]" In check_libcxx_string(const std::filesystem::__cxx11::filesystem_error&):556 Assertion TEST_CHECK(format == Err.what()) failed. in file: /app/llvm-project/libcxx/test/support/filesystem_test_helper.h filesystem_error::what() does not match expected output: expected: "filesystem error: in copy_file: File exists [/tmp/test.c01024/file1] [/tmp/test.c01024/file1]" actual: "filesystem error: cannot copy file: File exists [/tmp/test.c01024/file1] [/tmp/test.c01024/file1]"

In dest_is_file():98 Assertion TEST_CHECK(!ec) failed. in file: create_directory.pass.cpp Summary for testsuite filesystem_create_directory_test_suite: 4 of 5 test cases passed. 14 of 15 assertions passed. 0 unsupported test cases.
In dest_is_file():98 Assertion TEST_CHECK(!ec) failed. in file: create_directory_with_attributes.pass.cpp In attr_dir_is_invalid():109 Assertion TEST_CHECK(create_directory(dest, file, ec) == false) failed. in file: create_directory_with_attributes.pass.cpp In attr_dir_is_invalid():110 Assertion TEST_CHECK(ErrorIs(ec, std::errc::not_a_directory)) failed. in file: create_directory_with_attributes.pass.cpp In attr_dir_is_invalid():112 Assertion TEST_REQUIRE(!exists(dest)) failed. in file: create_directory_with_attributes.pass.cpp In dest_is_symlink():127 Assertion TEST_CHECK(!ec) failed. in file: create_directory_with_attributes.pass.cpp Summary for testsuite filesystem_create_directory_test_suite: 4 of 7 test cases passed. 15 of 20 assertions passed. 0 unsupported test cases.
In equivalent_reports_error_if_input_dne():66 Assertion TEST_CHECK(ec) failed. in file: equivalent.pass.cpp In equivalent_reports_error_if_input_dne():72 Assertion TEST_CHECK(ec) failed. in file: equivalent.pass.cpp In equivalent_reports_error_if_input_dne():76 Assertion TEST_CHECK_THROW(filesystem_error,equivalent(DNE, E)) failed. in file: equivalent.pass.cpp In equivalent_reports_error_if_input_dne():77 Assertion TEST_CHECK_THROW(filesystem_error,equivalent(E, DNE)) failed. in file: equivalent.pass.cpp Test case FAILED with uncaught exception: last checkpoint near equivalent.pass.cpp::109 void equivalent_test_suite::equivalent_is_other_succeeds() Summary for testsuite equivalent_test_suite: 3 of 5 test cases passed. 27 of 31 assertions passed. 0 unsupported test cases.
In test_exists_fails():82 Assertion TEST_CHECK(exists(file, ec) == false) failed. in file: exists.pass.cpp In test_exists_fails():83 Assertion TEST_CHECK(ec) failed. in file: exists.pass.cpp In test_exists_fails():85 Assertion TEST_CHECK_THROW(filesystem_error,exists(file)) failed. in file: exists.pass.cpp Summary for testsuite exists_test_suite: 4 of 5 test cases passed. 15 of 18 assertions passed. 0 unsupported test cases.
In check_libcxx_string(const std::filesystem::__cxx11::filesystem_error&):556 Assertion TEST_CHECK(format == Err.what()) failed. in file: /app/llvm-project/libcxx/test/support/filesystem_test_helper.h filesystem_error::what() does not match expected output: expected: "filesystem error: in file_size: Is a directory [/tmp/test.19887a/dir1]" actual: "filesystem error: cannot get file size: Is a directory [/tmp/test.19887a/dir1]" In check_libcxx_string(const std::filesystem::__cxx11::filesystem_error&):556 Assertion TEST_CHECK(format == Err.what()) failed. in file: /app/llvm-project/libcxx/test/support/filesystem_test_helper.h filesystem_error::what() does not match expected output: expected: "filesystem error: in file_size: Is a directory [/tmp/test.19887a/symlink_to_dir]" actual: "filesystem error: cannot get file size: Is a directory [/tmp/test.19887a/symlink_to_dir]" In check_libcxx_string(const std::filesystem::__cxx11::filesystem_error&):556 Assertion TEST_CHECK(format == Err.what()) failed. in file: /app/llvm-project/libcxx/test/support/filesystem_test_helper.h filesystem_error::what() does not match expected output: expected: "filesystem error: in file_size: No such file or directory [/tmp/test.19887a/bad_symlink]" actual: "filesystem error: cannot get file size: No such file or directory [/tmp/test.19887a/bad_symlink]" In check_libcxx_string(const std::filesystem::__cxx11::filesystem_error&):556 Assertion TEST_CHECK(format == Err.what()) failed. in file: /app/llvm-project/libcxx/test/support/filesystem_test_helper.h filesystem_error::what() does not match expected output: expected: "filesystem error: in file_size: No such file or directory [/tmp/test.19887a/DNE]" actual: "filesystem error: cannot get file size: No such file or directory [/tmp/test.19887a/DNE]" In check_libcxx_string(const std::filesystem::__cxx11::filesystem_error&):556 Assertion TEST_CHECK(format == Err.what()) failed. in file: /app/llvm-project/libcxx/test/support/filesystem_test_helper.h filesystem_error::what() does not match expected output: expected: "filesystem error: in file_size: No such file or directory [""]" actual: "filesystem error: cannot get file size: No such file or directory []" Summary for testsuite file_size_test_suite: 4 of 5 test cases passed. 35 of 40 assertions passed. 0 unsupported test cases.
In test_is_block_file_fails():79 Assertion TEST_CHECK(ec) failed. in file: is_block_file.pass.cpp In test_is_block_file_fails():81 Assertion TEST_CHECK_THROW(filesystem_error,is_block_file(file)) failed. in file: is_block_file.pass.cpp Summary for testsuite is_block_file_test_suite: 3 of 4 test cases passed. 12 of 14 assertions passed. 0 unsupported test cases.
In test_is_character_file_fails():79 Assertion TEST_CHECK(ec) failed. in file: is_character_file.pass.cpp In test_is_character_file_fails():81 Assertion TEST_CHECK_THROW(filesystem_error,is_character_file(file)) failed. in file: is_character_file.pass.cpp Summary for testsuite is_character_file_test_suite: 3 of 4 test cases passed. 12 of 14 assertions passed. 0 unsupported test cases.
In test_is_directory_fails():86 Assertion TEST_CHECK(is_directory(dir2, ec) == false) failed. in file: is_directory.pass.cpp In test_is_directory_fails():87 Assertion TEST_CHECK(ec) failed. in file: is_directory.pass.cpp In test_is_directory_fails():89 Assertion TEST_CHECK_THROW(filesystem_error,is_directory(dir2)) failed. in file: is_directory.pass.cpp Summary for testsuite is_directory_test_suite: 4 of 5 test cases passed. 14 of 17 assertions passed. 0 unsupported test cases.
In test_is_empty_fails():76 Assertion TEST_CHECK(is_empty(dir2, ec) == false) failed. in file: is_empty.pass.cpp In test_is_empty_fails():77 Assertion TEST_CHECK(ec) failed. in file: is_empty.pass.cpp In test_is_empty_fails():79 Assertion TEST_CHECK_THROW(filesystem_error,is_empty(dir2)) failed. in file: is_empty.pass.cpp In test_directory_access_denied():91 Assertion TEST_CHECK(ec) failed. in file: is_empty.pass.cpp In test_directory_access_denied():94 Assertion TEST_CHECK_THROW(filesystem_error,is_empty(dir)) failed. in file: is_empty.pass.cpp Summary for testsuite is_empty_test_suite: 6 of 8 test cases passed. 15 of 20 assertions passed. 0 unsupported test cases.
In test_is_fifo_fails():79 Assertion TEST_CHECK(ec) failed. in file: is_fifo.pass.cpp In test_is_fifo_fails():81 Assertion TEST_CHECK_THROW(filesystem_error,is_fifo(file)) failed. in file: is_fifo.pass.cpp Summary for testsuite is_fifo_test_suite: 3 of 4 test cases passed. 12 of 14 assertions passed. 0 unsupported test cases.
In test_is_other_fails():79 Assertion TEST_CHECK(ec) failed. in file: is_other.pass.cpp In test_is_other_fails():81 Assertion TEST_CHECK_THROW(filesystem_error,is_other(file)) failed. in file: is_other.pass.cpp Summary for testsuite is_other_test_suite: 3 of 4 test cases passed. 12 of 14 assertions passed. 0 unsupported test cases.
In test_is_regular_file_fails():81 Assertion TEST_CHECK(is_regular_file(file, ec) == false) failed. in file: is_regular_file.pass.cpp In test_is_regular_file_fails():82 Assertion TEST_CHECK(ec) failed. in file: is_regular_file.pass.cpp In test_is_regular_file_fails():84 Assertion TEST_CHECK_THROW(filesystem_error,is_regular_file(file)) failed. in file: is_regular_file.pass.cpp Summary for testsuite is_regular_file_test_suite: 3 of 4 test cases passed. 13 of 16 assertions passed. 0 unsupported test cases.
In test_is_socket_fails():79 Assertion TEST_CHECK(ec) failed. in file: is_socket.pass.cpp In test_is_socket_fails():81 Assertion TEST_CHECK_THROW(filesystem_error,is_socket(file)) failed. in file: is_socket.pass.cpp Summary for testsuite is_socket_test_suite: 3 of 4 test cases passed. 12 of 14 assertions passed. 0 unsupported test cases.
In test_is_symlink_fails():101 Assertion TEST_CHECK(ec) failed. in file: is_symlink.pass.cpp In test_is_symlink_fails():103 Assertion TEST_CHECK_THROW(filesystem_error,is_symlink(file)) failed. in file: is_symlink.pass.cpp Summary for testsuite is_symlink_test_suite: 4 of 5 test cases passed. 19 of 21 assertions passed. 0 unsupported test cases.
In basic_test():113 Assertion TEST_CHECK(PathEq(output, TC.expect)) failed. in file: proximate.pass.cpp TEST CASE #2 FAILED: Input: '/' Base: 'a' Expected: '..' Output: '/' Lex Prox: '/' Canon Input: "/" Canon Base: "a" In basic_test():113 Assertion TEST_CHECK(PathEq(output, TC.expect)) failed. in file: proximate.pass.cpp TEST CASE #3 FAILED: Input: '/' Base: 'a' Expected: '../..' Output: '/' Lex Prox: '/' Canon Input: "/" Canon Base: "a" In basic_test():113 Assertion TEST_CHECK(PathEq(output, TC.expect)) failed. in file: proximate.pass.cpp TEST CASE #6 FAILED: Input: '/' Base: 'a' Expected: '..' Output: '/' Lex Prox: '/' Canon Input: "/" Canon Base: "a" In basic_test():113 Assertion TEST_CHECK(PathEq(output, TC.expect)) failed. in file: proximate.pass.cpp TEST CASE #7 FAILED: Input: '/' Base: 'a/b' Expected: '../..' Output: '/' Lex Prox: '/' Canon Input: "/" Canon Base: "a/b" In basic_test():113 Assertion TEST_CHECK(PathEq(output, TC.expect)) failed. in file: proximate.pass.cpp TEST CASE #8 FAILED: Input: '/' Base: 'a/b/' Expected: '../..' Output: '/' Lex Prox: '/' Canon Input: "/" Canon Base: "a/b/" In basic_test():113 Assertion TEST_CHECK(PathEq(output, TC.expect)) failed. in file: proximate.pass.cpp TEST CASE #11 FAILED: Input: 'a' Base: '/net' Expected: '../a' Output: 'a' Lex Prox: 'a' Canon Input: "a" Canon Base: "/net" In basic_test():113 Assertion TEST_CHECK(PathEq(output, TC.expect)) failed. in file: proximate.pass.cpp TEST CASE #16 FAILED: Input: '//base' Base: 'a' Expected: '../base' Output: '/base' Lex Prox: '/base' Canon Input: "/base" Canon Base: "a" Summary for testsuite filesystem_proximate_path_test_suite: 1 of 2 test cases passed. 1 of 8 assertions passed. 0 unsupported test cases.
In test_signature_0():34 Assertion TEST_CHECK(output == std::string(fs::current_path())) failed. in file: relative.pass.cpp Summary for testsuite filesystem_proximate_path_test_suite: 13 of 14 test cases passed. 13 of 14 assertions passed. 0 unsupported test cases.
In test_error_reporting():68 Assertion TEST_CHECK(!fs::remove(p, ec)) failed. in file: remove.pass.cpp In test_error_reporting():69 Assertion TEST_CHECK(ec) failed. in file: remove.pass.cpp In test_error_reporting():70 Assertion TEST_CHECK(checkThrow(p, ec)) failed. in file: remove.pass.cpp Summary for testsuite filesystem_remove_test_suite: 2 of 3 test cases passed. 19 of 22 assertions passed. 0 unsupported test cases.
In test_error_reporting():71 Assertion TEST_CHECK(fs::remove_all(p, ec) == BadRet) failed. in file: remove_all.pass.cpp In test_error_reporting():72 Assertion TEST_CHECK(ec) failed. in file: remove_all.pass.cpp In test_error_reporting():73 Assertion TEST_CHECK(checkThrow(p, ec)) failed. in file: remove_all.pass.cpp Summary for testsuite filesystem_remove_all_test_suite: 4 of 5 test cases passed. 30 of 33 assertions passed. 0 unsupported test cases.
In test_status_cannot_resolve():86 Assertion TEST_CHECK(ec == TC.expect_ec) failed. in file: status.pass.cpp In test_status_cannot_resolve():87 Assertion TEST_CHECK(st.type() == file_type::none) failed. in file: status.pass.cpp In test_status_cannot_resolve():88 Assertion TEST_CHECK(st.permissions() == perms::unknown) failed. in file: status.pass.cpp In test_status_cannot_resolve():86 Assertion TEST_CHECK(ec == TC.expect_ec) failed. in file: status.pass.cpp In test_status_cannot_resolve():87 Assertion TEST_CHECK(st.type() == file_type::none) failed. in file: status.pass.cpp In test_status_cannot_resolve():88 Assertion TEST_CHECK(st.permissions() == perms::unknown) failed. in file: status.pass.cpp Summary for testsuite filesystem_status_test_suite: 3 of 4 test cases passed. 61 of 67 assertions passed. 1 unsupported test case.
In test_symlink_status_cannot_resolve():79 Assertion TEST_CHECK(ec == expect_ec) failed. in file: symlink_status.pass.cpp In test_symlink_status_cannot_resolve():80 Assertion TEST_CHECK(st.type() == file_type::none) failed. in file: symlink_status.pass.cpp In test_symlink_status_cannot_resolve():81 Assertion TEST_CHECK(st.permissions() == perms::unknown) failed. in file: symlink_status.pass.cpp In test_symlink_status_cannot_resolve():79 Assertion TEST_CHECK(ec == expect_ec) failed. in file: symlink_status.pass.cpp In test_symlink_status_cannot_resolve():80 Assertion TEST_CHECK(st.type() == file_type::none) failed. in file: symlink_status.pass.cpp In test_symlink_status_cannot_resolve():81 Assertion TEST_CHECK(st.permissions() == perms::unknown) failed. in file: symlink_status.pass.cpp Summary for testsuite filesystem_symlink_status_test_suite: 3 of 4 test cases passed. 61 of 67 assertions passed. 1 unsupported test case.
In basic_tests():78 Assertion TEST_CHECK(ec == expect_ec) failed. in file: temp_directory_path.pass.cpp In basic_tests():96 Assertion TEST_CHECK(ec == std::make_error_code(std::errc::permission_denied)) failed. in file: temp_directory_path.pass.cpp In basic_tests():97 Assertion TEST_CHECK(ret == "") failed. in file: temp_directory_path.pass.cpp In basic_tests():78 Assertion TEST_CHECK(ec == expect_ec) failed. in file: temp_directory_path.pass.cpp In basic_tests():96 Assertion TEST_CHECK(ec == std::make_error_code(std::errc::permission_denied)) failed. in file: temp_directory_path.pass.cpp In basic_tests():97 Assertion TEST_CHECK(ret == "") failed. in file: temp_directory_path.pass.cpp In basic_tests():78 Assertion TEST_CHECK(ec == expect_ec) failed. in file: temp_directory_path.pass.cpp In basic_tests():96 Assertion TEST_CHECK(ec == std::make_error_code(std::errc::permission_denied)) failed. in file: temp_directory_path.pass.cpp In basic_tests():97 Assertion TEST_CHECK(ret == "") failed. in file: temp_directory_path.pass.cpp In basic_tests():78 Assertion TEST_CHECK(ec == expect_ec) failed. in file: temp_directory_path.pass.cpp In basic_tests():96 Assertion TEST_CHECK(ec == std::make_error_code(std::errc::permission_denied)) failed. in file: temp_directory_path.pass.cpp In basic_tests():97 Assertion TEST_CHECK(ret == "") failed. in file: temp_directory_path.pass.cpp Summary for testsuite filesystem_temp_directory_path_test_suite: 1 of 2 test cases passed. 55 of 67 assertions passed. 0 unsupported test cases.
TEST CASE #1 FAILED: Input: '' Expected: '/' Output: '' TEST CASE #7 FAILED: Input: 'a/b' Expected: '/a/b' Output: 'a/b' TEST CASE #8 FAILED: Input: 'a' Expected: '/a' Output: 'a' TEST CASE #9 FAILED: Input: 'a/b/' Expected: '/a/b/' Output: 'a/b/'
terminate called after throwing an instance of 'std::runtime_error' what(): locale::facet::_S_create_c_locale name not valid
terminate called after throwing an instance of 'std::runtime_error' what(): locale::facet::_S_create_c_locale name not valid
terminate called after throwing an instance of 'std::runtime_error' what(): locale::facet::_S_create_c_locale name not valid
terminate called after throwing an instance of 'std::runtime_error' what(): locale::facet::_S_create_c_locale name not valid
Assertion failed: is.gcount() == 10 (streambuf.pass.cpp: main: 75)
Assertion failed: is.fail() (ws.pass.cpp: main: 67)
terminate called after throwing an instance of 'std::runtime_error' what(): locale::facet::_S_create_c_locale name not valid
terminate called after throwing an instance of 'std::runtime_error' what(): locale::facet::_S_create_c_locale name not valid
Assertion failed: std::ios_base::sync_with_stdio(true) (sync_with_stdio.pass.cpp: main: 23)
terminate called after throwing an instance of 'std::runtime_error' what(): locale::facet::_S_create_c_locale name not valid
terminate called after throwing an instance of 'std::runtime_error' what(): locale::facet::_S_create_c_locale name not valid
terminate called after throwing an instance of 'std::runtime_error' what(): locale::facet::_S_create_c_locale name not valid
terminate called after throwing an instance of 'std::runtime_error' what(): locale::facet::_S_create_c_locale name not valid
terminate called after throwing an instance of 'std::runtime_error' what(): locale::facet::_S_create_c_locale name not valid
terminate called after throwing an instance of 'std::runtime_error' what(): locale::facet::_S_create_c_locale name not valid
terminate called after throwing an instance of 'std::runtime_error' what(): locale::facet::_S_create_c_locale name not valid
terminate called after throwing an instance of 'std::runtime_error' what(): locale::facet::_S_create_c_locale name not valid
terminate called after throwing an instance of 'std::runtime_error' what(): locale::facet::_S_create_c_locale name not valid
Assertion failed: sb.pubseekpos(3, std::ios_base::in | std::ios_base::out) == -1 (seekpos.pass.cpp: main: 27)
Assertion failed: *i == 'b' (proxy.pass.cpp: main: 28)
Assertion failed: false (new_align_val_t.pass.cpp: test_throw_max_size: 73)
Assertion failed: new_handler_called == 1 (new_align_val_t_nothrow.pass.cpp: operator(): 71)
Assertion failed: 1 == unsized_delete_called (sized_delete_array11.pass.cpp: main: 66)
Assertion failed: false (new_align_val_t.pass.cpp: test_throw_max_size: 73)
Assertion failed: new_handler_called == 1 (new_align_val_t_nothrow.pass.cpp: operator(): 71)
Assertion failed: 1 == unsized_delete_called (sized_delete11.pass.cpp: main: 56)
terminate called after throwing an instance of 'std::runtime_error' what(): locale::facet::_S_create_c_locale name not valid
terminate called after throwing an instance of 'std::runtime_error' what(): locale::facet::_S_create_c_locale name not valid
terminate called after throwing an instance of 'std::runtime_error' what(): locale::facet::_S_create_c_locale name not valid
terminate called after throwing an instance of 'std::runtime_error' what(): locale::facet::_S_create_c_locale name not valid
Assertion failed: F::classic_table() != 0 (classic_table.pass.cpp: main: 23)
terminate called after throwing an instance of 'std::runtime_error' what(): locale::facet::_S_create_c_locale name not valid
terminate called after throwing an instance of 'std::runtime_error' what(): locale::facet::_S_create_c_locale name not valid
Assertion failed: f32_16.out(mbs32_16, &c32x, &c32x + 1, c_c32p, c16c + 0, c16c + 4, c16cp) == F32_8::error (utf_sanity_check.pass.cpp: main: 66)
Assertion failed: f.unshift(mbs, to.data(), to.data() + to.size(), to_next) == F::ok (wchar_t_unshift.pass.cpp: main: 34)
terminate called after throwing an instance of 'std::runtime_error' what(): locale::facet::_S_create_c_locale name not valid
terminate called after throwing an instance of 'std::runtime_error' what(): locale::facet::_S_create_c_locale name not valid
terminate called after throwing an instance of 'std::runtime_error' what(): locale::facet::_S_create_c_locale name not valid
terminate called after throwing an instance of 'std::runtime_error' what(): locale::facet::_S_create_c_locale name not valid
terminate called after throwing an instance of 'std::runtime_error' what(): locale::facet::_S_create_c_locale name not valid
terminate called after throwing an instance of 'std::runtime_error' what(): locale::facet::_S_create_c_locale name not valid
terminate called after throwing an instance of 'std::runtime_error' what(): locale::facet::_S_create_c_locale name not valid
terminate called after throwing an instance of 'std::runtime_error' what(): locale::facet::_S_create_c_locale name not valid
terminate called after throwing an instance of 'std::runtime_error' what(): locale::facet::_S_create_c_locale name not valid
terminate called after throwing an instance of 'std::runtime_error' what(): locale::facet::_S_create_c_locale name not valid
terminate called after throwing an instance of 'std::runtime_error' what(): locale::facet::_S_create_c_locale name not valid
terminate called after throwing an instance of 'std::runtime_error' what(): locale::facet::_S_create_c_locale name not valid
terminate called after throwing an instance of 'std::runtime_error' what(): locale::facet::_S_create_c_locale name not valid
terminate called after throwing an instance of 'std::runtime_error' what(): locale::facet::_S_create_c_locale name not valid
terminate called after throwing an instance of 'std::runtime_error' what(): locale::facet::_S_create_c_locale name not valid
terminate called after throwing an instance of 'std::runtime_error' what(): locale::facet::_S_create_c_locale name not valid
terminate called after throwing an instance of 'std::runtime_error' what(): locale::facet::_S_create_c_locale name not valid
terminate called after throwing an instance of 'std::runtime_error' what(): locale::facet::_S_create_c_locale name not valid
terminate called after throwing an instance of 'std::runtime_error' what(): locale::facet::_S_create_c_locale name not valid
terminate called after throwing an instance of 'std::runtime_error' what(): locale::facet::_S_create_c_locale name not valid
terminate called after throwing an instance of 'std::runtime_error' what(): locale::facet::_S_create_c_locale name not valid
terminate called after throwing an instance of 'std::runtime_error' what(): locale::facet::_S_create_c_locale name not valid
terminate called after throwing an instance of 'std::runtime_error' what(): locale::facet::_S_create_c_locale name not valid
terminate called after throwing an instance of 'std::runtime_error' what(): locale::facet::_S_create_c_locale name not valid
Assertion failed: f.decimal_point() == std::numeric_limits<char>::max() (decimal_point.pass.cpp: main: 63)
terminate called after throwing an instance of 'std::runtime_error' what(): locale::facet::_S_create_c_locale name not valid
terminate called after throwing an instance of 'std::runtime_error' what(): locale::facet::_S_create_c_locale name not valid
terminate called after throwing an instance of 'std::runtime_error' what(): locale::facet::_S_create_c_locale name not valid
terminate called after throwing an instance of 'std::runtime_error' what(): locale::facet::_S_create_c_locale name not valid
terminate called after throwing an instance of 'std::runtime_error' what(): locale::facet::_S_create_c_locale name not valid
terminate called after throwing an instance of 'std::runtime_error' what(): locale::facet::_S_create_c_locale name not valid
Assertion failed: f.thousands_sep() == std::numeric_limits<char>::max() (thousands_sep.pass.cpp: main: 66)
Assertion failed: f.decimal_point() == std::numeric_limits<char>::max() (decimal_point.pass.cpp: main: 62)
Assertion failed: f.negative_sign() == "-" (negative_sign.pass.cpp: main: 63)
Assertion failed: f.thousands_sep() == std::numeric_limits<char>::max() (thousands_sep.pass.cpp: main: 62)
Assertion failed: ex == "-0x0;p+0" (put_double.pass.cpp: test7: 14429)
Assertion failed: ex == "0_123_46_7" (put_long.pass.cpp: main: 186)
Assertion failed: ex == "nan" (put_long_double.pass.cpp: test5: 10889)
Assertion failed: ex == "0_123_46_7" (put_long_long.pass.cpp: main: 186)
Assertion failed: ex == "0_123_46_7" (put_unsigned_long.pass.cpp: main: 186)
Assertion failed: ex == "0_123_46_7" (put_unsigned_long_long.pass.cpp: main: 186)
Assertion failed: err == ios.eofbit (get_bool.pass.cpp: main: 203)
Assertion failed: iter.base() == str+sizeof(str)-1 (get_double.pass.cpp: main: 107)
Assertion failed: iter.base() == str+sizeof(str)-1 (get_float.pass.cpp: main: 96)
Assertion failed: iter.base() == str+sizeof(str)-1 (get_long.pass.cpp: main: 217)
Assertion failed: iter.base() == str+sizeof(str)-1 (get_long_double.pass.cpp: main: 96)
Assertion failed: f.date_order() == std::time_base::mdy (date_order.pass.cpp: main: 41)
Assertion failed: f.date_order() == std::time_base::mdy (date_order_wide.pass.cpp: main: 41)
Assertion failed: f.date_order() == std::time_base::mdy (date_order.pass.cpp: main: 33)
Assertion failed: i.base() == in+sizeof(in)-1 (get_date.pass.cpp: main: 46)
Assertion failed: i.base() == in+sizeof(in)/sizeof(in[0])-1 (get_date_wide.pass.cpp: main: 46)
Assertion failed: i.base() == in+sizeof(in)-1 (get_many.pass.cpp: main: 47)
Assertion failed: t.tm_year == 100 (get_year.pass.cpp: main: 46)
terminate called after throwing an instance of 'std::runtime_error' what(): locale::facet::_S_create_c_locale name not valid
terminate called after throwing an instance of 'std::runtime_error' what(): locale::facet::_S_create_c_locale name not valid
terminate called after throwing an instance of 'std::runtime_error' what(): locale::facet::_S_create_c_locale name not valid
Assertion failed: f.pbase() == 0 (overflow.pass.cpp: main: 47)
Assertion failed: f.sbumpc() == L'1' (pbackfail.pass.cpp: main: 49)
Assertion failed: buf[0] == L'v' (seekoff.pass.cpp: main: 47)
Assertion failed: f.eback() == 0 (underflow.pass.cpp: main: 49)
Assertion failed: false (ctor_err_string.pass.cpp: main: 36)
terminate called after throwing an instance of 'std::runtime_error' what(): locale::facet::_S_create_c_locale name not valid
terminate called after throwing an instance of 'std::runtime_error' what(): locale::facet::_S_create_c_locale name not valid
terminate called after throwing an instance of 'std::runtime_error' what(): locale::facet::_S_create_c_locale name not valid
terminate called after throwing an instance of 'std::runtime_error' what(): locale::facet::_S_create_c_locale name not valid
terminate called after throwing an instance of 'std::runtime_error' what(): locale::facet::_S_create_c_locale name not valid
terminate called after throwing an instance of 'std::runtime_error' what(): locale::facet::_S_create_c_locale name not valid
terminate called after throwing an instance of 'std::runtime_error' what(): locale::facet::_S_create_c_locale name not valid
terminate called after throwing an instance of 'std::runtime_error' what(): locale::facet::_S_create_c_locale name not valid
terminate called after throwing an instance of 'std::runtime_error' what(): locale::facet::_S_create_c_locale name not valid
Assertion failed: loc3.name() == "*" (combine.pass.cpp: main: 75)
terminate called after throwing an instance of 'std::runtime_error' what(): locale::facet::_S_create_c_locale name not valid
terminate called after throwing an instance of 'std::runtime_error' what(): locale::facet::_S_create_c_locale name not valid
terminate called after throwing an instance of 'std::runtime_error' what(): locale::facet::_S_create_c_locale name not valid
Assertion failed: lhs / rhs == x (complex_divide_complex.pass.cpp: test: 25)
Assertion failed: lhs / rhs == x (scalar_divide_complex.pass.cpp: test: 24)
Assertion failed: acos(c) == x (acos.pass.cpp: test: 25)
Assertion failed: acosh(c) == x (acosh.pass.cpp: test: 25)
Assertion failed: std::isinf(r.imag()) (asin.pass.cpp: test_edges: 86)
Assertion failed: std::isinf(r.real()) (asinh.pass.cpp: test_edges: 88)
Assertion failed: imag(r) == imag(z) (atan.pass.cpp: test_edges: 55)
Assertion failed: std::signbit(r.imag()) == std::signbit(testcases[i].imag()) (atanh.pass.cpp: test_edges: 120)
Assertion failed: std::signbit(r.imag()) == std::signbit(testcases[i].imag()) (cosh.pass.cpp: test_edges: 72)
Assertion failed: std::isnan(real(z)) (pow_complex_scalar.pass.cpp: test_edges: 47)
Assertion failed: std::isnan(real(z)) (pow_scalar_complex.pass.cpp: test_edges: 47)
Assertion failed: r.real() == 1 (tanh.pass.cpp: test_edges: 71)
Assertion failed: std::isinf(r) && r > 0 (norm.pass.cpp: test_edges: 45)
Assertion failed: c == NaN || c == non_zero_nan (polar.pass.cpp: test_edges: 72)
Assertion failed: std::signbit(imag(r)) == std::signbit(imag(testcases[i])) (proj.pass.cpp: test_edges: 55)
Assertion failed: os.str() == a (ctor_result_type.pass.cpp: test1: 32)
Assertion failed: os.str() == a (ctor_sseq.pass.cpp: test1: 34)
Assertion failed: os.str() == a (ctor_result_type.pass.cpp: test1: 32)
Assertion failed: os.str() == a (ctor_sseq.pass.cpp: test1: 34)
terminate called after throwing an instance of 'std::runtime_error' what(): random_device::random_device(const std::string&): unsupported token
terminate called after throwing an instance of 'std::runtime_error' what(): random_device::random_device(const std::string&): unsupported token
Assertion failed: std::abs((kurtosis - x_kurtosis) / x_kurtosis) < 0.04 (eval.pass.cpp: test1: 74)
Assertion failed: std::abs((kurtosis - x_kurtosis) / x_kurtosis) < 0.04 (eval_param.pass.cpp: main: 75)
Assertion failed: std::abs((skew - x_skew) / x_skew) < 0.01 (eval.pass.cpp: test3: 168)
Assertion failed: std::abs((skew - x_skew) / x_skew) < 0.01 (eval_param.pass.cpp: main: 158)
Assertion failed: std::abs((kurtosis - x_kurtosis) / x_kurtosis) < 0.01 (eval.pass.cpp: test2: 116)
Assertion failed: std::abs((kurtosis - x_kurtosis) / x_kurtosis) < 0.01 (eval_param.pass.cpp: main: 75)
Assertion failed: m == INFINITY (max.pass.cpp: main: 27)
Assertion failed: d.min() == -INFINITY (min.pass.cpp: main: 26)
Assertion failed: std::abs((kurtosis - x_kurtosis) / x_kurtosis) < 0.01 (eval.pass.cpp: main: 112)
Assertion failed: std::abs((kurtosis - x_kurtosis) / x_kurtosis) < 0.01 (eval_param.pass.cpp: main: 75)
Assertion failed: m == INFINITY (max.pass.cpp: main: 27)
Assertion failed: std::abs(f(u[i], p.m(), p.n()) - double(i)/N) < .01 (eval_param.pass.cpp: main: 70)
Assertion failed: m == INFINITY (max.pass.cpp: main: 27)
Assertion failed: m == INFINITY (max.pass.cpp: main: 27)
Assertion failed: d1 == d2 (io.pass.cpp: main: 40)
Assertion failed: m == INFINITY (max.pass.cpp: main: 27)
Assertion failed: d.min() == -INFINITY (min.pass.cpp: main: 26)
Assertion failed: std::abs(skew - x_skew) < 0.01 (eval.pass.cpp: main: 67)
Assertion failed: std::abs(skew - x_skew) < 0.01 (eval_param.pass.cpp: main: 69)
Assertion failed: m == INFINITY (max.pass.cpp: main: 27)
Assertion failed: d.min() == -INFINITY (min.pass.cpp: main: 26)
Assertion failed: m == std::numeric_limits<D::result_type>::infinity() (max.pass.cpp: main: 27)
Assertion failed: m == INFINITY (max.pass.cpp: main: 27)
Assertion failed: d.min() == -INFINITY (min.pass.cpp: main: 26)
Assertion failed: std::abs((kurtosis - x_kurtosis) / x_kurtosis) < 0.01 (eval.pass.cpp: main: 111)
Assertion failed: std::abs((kurtosis - x_kurtosis) / x_kurtosis) < 0.01 (eval_param.pass.cpp: main: 74)
Assertion failed: m == INFINITY (max.pass.cpp: main: 27)
Assertion failed: std::abs((kurtosis - x_kurtosis) / x_kurtosis) < 0.01 (eval.pass.cpp: main: 211)
Assertion failed: std::abs((kurtosis - x_kurtosis) / x_kurtosis) < 0.01 (eval_param.pass.cpp: main: 156)
Assertion failed: m == INFINITY (max.pass.cpp: main: 27)
terminate called after throwing an instance of 'std::length_error' what(): vector::reserve
Assertion failed: d1 == d2 (io.pass.cpp: main: 43)
terminate called after throwing an instance of 'std::length_error' what(): vector::reserve
Assertion failed: dn[0] == 0 (ctor_func.pass.cpp: main: 39)

Assertion failed: dn[0] == 0 (param_ctor_func.pass.cpp: main: 40)
Assertion failed: os.str() == a (ctor_result_type.pass.cpp: test1: 126)
Assertion failed: os.str() == a (ctor_sseq.pass.cpp: test1: 188)
Assertion failed: os.str() == a (ctor_result_type.pass.cpp: test1: 32)
Assertion failed: os.str() == a (ctor_sseq.pass.cpp: test1: 34)
Assertion failed: e() == 399268537u (default_random_engine.pass.cpp: main: 22)
terminate called after throwing an instance of 'std::runtime_error' what(): locale::facet::_S_create_c_locale name not valid
terminate called after throwing an instance of 'std::runtime_error' what(): locale::facet::_S_create_c_locale name not valid
terminate called after throwing an instance of 'std::runtime_error' what(): locale::facet::_S_create_c_locale name not valid
Assertion failed: false (exponential.pass.cpp: main: 36)
terminate called after throwing an instance of 'std::regex_error' what(): Unexpected escape character.
terminate called after throwing an instance of 'std::regex_error' what(): Unexpected escape character.
Assertion failed: false (exponential.pass.cpp: main: 33)
terminate called after throwing an instance of 'std::runtime_error' what(): locale::facet::_S_create_c_locale name not valid
terminate called after throwing an instance of 'std::runtime_error' what(): locale::facet::_S_create_c_locale name not valid
terminate called after throwing an instance of 'std::runtime_error' what(): locale::facet::_S_create_c_locale name not valid
Assertion failed: false (exponential.pass.cpp: main: 36)
terminate called after throwing an instance of 'std::regex_error' what(): Unexpected escape character.
Assertion failed: !std::regex_search("ab", std::regex("a(?=^)b")) (lookahead.pass.cpp: main: 27)
Assertion failed: e.what() == std::string("The expression contained an invalid collating element name.") (regex_error.pass.cpp: main: 29)
Assertion failed: std::regex_constants::error_collate != 0 (error_type.pass.cpp: main: 40)
Assertion failed: regex_match(str1 + 1, str1 + 2, regex("^a"), regex_constants::match_not_bol | regex_constants::match_prev_avail) (match_prev_avail.pass.cpp: main: 24)
Assertion failed: std::regex_constants::ECMAScript == 0 (syntax_option_type.pass.cpp: main: 44)
Assertion failed: e.code() == std::regex_constants::error_badbrace (excessive_brace_count.pass.cpp: main: 26)
Assertion failed: e.code() == std::regex_constants::error_badbrace (excessive_brace_min_max.pass.cpp: main: 51)
Assertion failed: error_badbackref_thrown("\\1abd", std::regex::extended) (bad_backref.pass.cpp: main: 37)
Assertion failed: error_ctype_thrown("[[::]]") (bad_ctype.pass.cpp: main: 34)
Assertion failed: error_escape_thrown("[\\a]") (bad_escape.pass.cpp: main: 34)
Assertion failed: error_range_thrown("([\\w-a])") (bad_range.pass.cpp: main: 34)
Assertion failed: error_badrepeat_thrown("?a") (bad_repeat.pass.cpp: main: 34)
terminate called after throwing an instance of 'std::regex_error' what(): Parenthesis is not closed.
terminate called after throwing an instance of 'std::runtime_error' what(): locale::facet::_S_create_c_locale name not valid
terminate called after throwing an instance of 'std::runtime_error' what(): locale::facet::_S_create_c_locale name not valid
terminate called after throwing an instance of 'std::runtime_error' what(): locale::facet::_S_create_c_locale name not valid
terminate called after throwing an instance of 'std::runtime_error' what(): locale::facet::_S_create_c_locale name not valid
Assertion failed: t.lookup_collatename(F(A), F(A + t.length(A))) == expected (lookup_collatename.pass.cpp: test: 39)
terminate called after throwing an instance of 'std::runtime_error' what(): locale::facet::_S_create_c_locale name not valid
terminate called after throwing an instance of 'std::runtime_error' what(): locale::facet::_S_create_c_locale name not valid
terminate called after throwing an instance of 'std::runtime_error' what(): locale::facet::_S_create_c_locale name not valid

Assertion failed: test_alloc_base::alloc_count == 1 (alloc_ctor.pass.cpp: main: 31)
Assertion failed: test_alloc_base::alloc_count == 2 (move_assign.pass.cpp: main: 30)
Assertion failed: test_alloc_base::alloc_count == 1 (move_ctor.pass.cpp: main: 30)
terminate called after throwing an instance of 'int'
terminate called after throwing an instance of 'int'
Assertion failed: test_alloc_base::alloc_count == 2 (swap.pass.cpp: main: 32)
Assertion failed: test_alloc_base::alloc_count == 1 (dtor.pass.cpp: main: 33)


Assertion failed: test_alloc_base::alloc_count == 1 (dtor.pass.cpp: main: 33)



Assertion failed: e.code().value() == EPERM (unlock.pass.cpp: main: 47)

terminate called after throwing an instance of 'int'
Assertion failed: f.target<Ref>() (copy_move.pass.cpp: main: 147)
Assertion failed: tn1 != pinf (floating.pass.cpp: test: 61)
Assertion failed: false (nullptr_t_deleter_throw.pass.cpp: main: 46)
Assertion failed: false (pointer_deleter_throw.pass.cpp: main: 46)
Assertion failed: false (pointer_throw.pass.cpp: main: 47)
Assertion failed: false (unique_ptr.pass.cpp: main: 93)
Assertion failed: false (char_ptr_ctor.pass.cpp: test_char_pointer_ctor: 32)
Assertion failed: result == N (bitset.pass.cpp: test: 37)
